0,TypeError,'int' object is not callable,0,
1,TypeError,'int' object is not callable,0,
2,TypeError,'int' object is not callable,0,
3,NameError,name 'data8' is not defined,0,
4,AttributeError,'NoneType' object has no attribute 'hello',0,
5,TypeError,'int' object is not callable,0,
6,NameError,name 'data8' is not defined,0,
7,SyntaxError,"invalid syntax (Temp/ipykernel_21084/1866965863.py, line 1)",0,
8,TypeError,'int' object is not callable,0,
9,TypeError,'int' object is not callable,0,
10,ValueError,invalid literal for int() with base 10: 'HI',0,
11,TypeError,'int' object is not callable,4,e
12,TypeError,'int' object is not callable,0,,2022-02-17 15:03:49.085163,"[('3(2)', 1)]","['Traceback (most recent call last):', '  File ""C:\\Users\\Selene\\miniconda3\\lib\\site-packages\\IPython\\core\\interactiveshell.py"", line 3444, in run_code', '    exec(code_obj, self.user_global_ns, self.user_ns)', '  File ""C:\\Users\\Selene\\AppData\\Local\\Temp/ipykernel_11572/305253956.py"", line 1, in <module>', '    3(2)', ""TypeError: 'int' object is not callable""]"
13,TypeError,'int' object is not callable,0,,2022-02-17 15:07:51.584320,"[('3(2)', 1)]","['Traceback (most recent call last):', '  File ""C:\\Users\\Selene\\miniconda3\\lib\\site-packages\\IPython\\core\\interactiveshell.py"", line 3444, in run_code', '    exec(code_obj, self.user_global_ns, self.user_ns)', '  File ""C:\\Users\\Selene\\AppData\\Local\\Temp/ipykernel_11572/305253956.py"", line 1, in <module>', '    3(2)', ""TypeError: 'int' object is not callable""]"
14,TypeError,'int' object is not callable,0,,2022-02-17 15:08:45.263074,"[('3(2)', 1)]","['Traceback (most recent call last):', '  File ""C:\\Users\\Selene\\miniconda3\\lib\\site-packages\\IPython\\core\\interactiveshell.py"", line 3444, in run_code', '    exec(code_obj, self.user_global_ns, self.user_ns)', '  File ""C:\\Users\\Selene\\AppData\\Local\\Temp/ipykernel_30476/305253956.py"", line 1, in <module>', '    3(2)', ""TypeError: 'int' object is not callable""]"
15,AttributeError,'NoneType' object has no attribute 'hello',0,,2022-02-17 15:10:29.468218,"[('a.hello', 2)]","['Traceback (most recent call last):', '  File ""C:\\Users\\Selene\\miniconda3\\lib\\site-packages\\IPython\\core\\interactiveshell.py"", line 3444, in run_code', '    exec(code_obj, self.user_global_ns, self.user_ns)', '  File ""C:\\Users\\Selene\\AppData\\Local\\Temp/ipykernel_30476/2399003099.py"", line 2, in <module>', '    a.hello', ""AttributeError: 'NoneType' object has no attribute 'hello'""]"
16,TypeError,'int' object is not callable,0,,2022-02-17 15:12:13.519095,"[('3(2)', 1)]","['Traceback (most recent call last):', '  File ""C:\\Users\\Selene\\miniconda3\\lib\\site-packages\\IPython\\core\\interactiveshell.py"", line 3444, in run_code', '    exec(code_obj, self.user_global_ns, self.user_ns)', '  File ""C:\\Users\\Selene\\AppData\\Local\\Temp/ipykernel_32672/305253956.py"", line 1, in <module>', '    3(2)', ""TypeError: 'int' object is not callable""]"
17,TypeError,'int' object is not callable,0,,2022-02-17 15:13:17.389792,"[('3(2)', 1)]","['Traceback (most recent call last):', '  File ""C:\\Users\\Selene\\miniconda3\\lib\\site-packages\\IPython\\core\\interactiveshell.py"", line 3444, in run_code', '    exec(code_obj, self.user_global_ns, self.user_ns)', '  File ""C:\\Users\\Selene\\AppData\\Local\\Temp/ipykernel_24444/305253956.py"", line 1, in <module>', '    3(2)', ""TypeError: 'int' object is not callable""]"
18,TypeError,'int' object is not callable,0,,2022-02-17 15:14:01.708167,"[('3(2)', 1)]","['Traceback (most recent call last):', '  File ""C:\\Users\\Selene\\miniconda3\\lib\\site-packages\\IPython\\core\\interactiveshell.py"", line 3444, in run_code', '    exec(code_obj, self.user_global_ns, self.user_ns)', '  File ""C:\\Users\\Selene\\AppData\\Local\\Temp/ipykernel_17336/305253956.py"", line 1, in <module>', '    3(2)', ""TypeError: 'int' object is not callable""]"
19,TypeError,'int' object is not callable,0,,2022-02-17 15:14:29.080790,"[('3(2)', 1)]","['Traceback (most recent call last):', '  File ""C:\\Users\\Selene\\miniconda3\\lib\\site-packages\\IPython\\core\\interactiveshell.py"", line 3444, in run_code', '    exec(code_obj, self.user_global_ns, self.user_ns)', '  File ""C:\\Users\\Selene\\AppData\\Local\\Temp/ipykernel_17100/305253956.py"", line 1, in <module>', '    3(2)', ""TypeError: 'int' object is not callable""]"
20,TypeError,'int' object is not callable,0,,2022-02-17 15:20:01.969309,"[('3(2)', 1)]","['Traceback (most recent call last):', '  File ""C:\\Users\\Selene\\miniconda3\\lib\\site-packages\\IPython\\core\\interactiveshell.py"", line 3444, in run_code', '    exec(code_obj, self.user_global_ns, self.user_ns)', '  File ""C:\\Users\\Selene\\AppData\\Local\\Temp/ipykernel_3892/305253956.py"", line 1, in <module>', '    3(2)', ""TypeError: 'int' object is not callable""]"
21,AttributeError,'NoneType' object has no attribute 'hello',0,,2022-02-17 15:20:13.379694,"[('a.hello', 2)]","['Traceback (most recent call last):', '  File ""C:\\Users\\Selene\\miniconda3\\lib\\site-packages\\IPython\\core\\interactiveshell.py"", line 3444, in run_code', '    exec(code_obj, self.user_global_ns, self.user_ns)', '  File ""C:\\Users\\Selene\\AppData\\Local\\Temp/ipykernel_3892/2399003099.py"", line 2, in <module>', '    a.hello', ""AttributeError: 'NoneType' object has no attribute 'hello'""]"
22,NameError,name 'data8' is not defined,0,,2022-02-17 15:20:21.799362,"[('data8', 1)]","['Traceback (most recent call last):', '  File ""C:\\Users\\Selene\\miniconda3\\lib\\site-packages\\IPython\\core\\interactiveshell.py"", line 3444, in run_code', '    exec(code_obj, self.user_global_ns, self.user_ns)', '  File ""C:\\Users\\Selene\\AppData\\Local\\Temp/ipykernel_3892/3759785821.py"", line 1, in <module>', '    data8', ""NameError: name 'data8' is not defined""]"
23,TypeError,'int' object is not callable,0,,2022-02-17 15:42:50.234226,"[('3(2)', 1)]","['Traceback (most recent call last):', '  File ""C:\\Users\\Selene\\miniconda3\\lib\\site-packages\\IPython\\core\\interactiveshell.py"", line 3444, in run_code', '    exec(code_obj, self.user_global_ns, self.user_ns)', '  File ""C:\\Users\\Selene\\AppData\\Local\\Temp/ipykernel_31692/305253956.py"", line 1, in <module>', '    3(2)', ""TypeError: 'int' object is not callable""]"
24,TypeError,'int' object is not callable,0,,2022-02-17 15:43:41.890531,"[('3(2)', 1)]","['Traceback (most recent call last):', '  File ""C:\\Users\\Selene\\miniconda3\\lib\\site-packages\\IPython\\core\\interactiveshell.py"", line 3444, in run_code', '    exec(code_obj, self.user_global_ns, self.user_ns)', '  File ""C:\\Users\\Selene\\AppData\\Local\\Temp/ipykernel_28652/305253956.py"", line 1, in <module>', '    3(2)', ""TypeError: 'int' object is not callable""]"
25,AttributeError,'NoneType' object has no attribute 'hello',0,,2022-02-17 15:43:47.258254,"[('a.hello', 2)]","['Traceback (most recent call last):', '  File ""C:\\Users\\Selene\\miniconda3\\lib\\site-packages\\IPython\\core\\interactiveshell.py"", line 3444, in run_code', '    exec(code_obj, self.user_global_ns, self.user_ns)', '  File ""C:\\Users\\Selene\\AppData\\Local\\Temp/ipykernel_28652/2399003099.py"", line 2, in <module>', '    a.hello', ""AttributeError: 'NoneType' object has no attribute 'hello'""]"
26,TypeError,'int' object is not callable,0,,2022-02-17 15:44:09.381395,"[('3(2)', 1)]","['Traceback (most recent call last):', '  File ""C:\\Users\\Selene\\miniconda3\\lib\\site-packages\\IPython\\core\\interactiveshell.py"", line 3444, in run_code', '    exec(code_obj, self.user_global_ns, self.user_ns)', '  File ""C:\\Users\\Selene\\AppData\\Local\\Temp/ipykernel_21792/305253956.py"", line 1, in <module>', '    3(2)', ""TypeError: 'int' object is not callable""]"
27,AttributeError,'NoneType' object has no attribute 'hello',0,,2022-02-17 15:44:18.231040,"[('a.hello', 2)]","['Traceback (most recent call last):', '  File ""C:\\Users\\Selene\\miniconda3\\lib\\site-packages\\IPython\\core\\interactiveshell.py"", line 3444, in run_code', '    exec(code_obj, self.user_global_ns, self.user_ns)', '  File ""C:\\Users\\Selene\\AppData\\Local\\Temp/ipykernel_21792/2399003099.py"", line 2, in <module>', '    a.hello', ""AttributeError: 'NoneType' object has no attribute 'hello'""]"
28,NameError,name 'data8' is not defined,0,,2022-02-17 15:44:32.520784,"[('data8', 1)]","['Traceback (most recent call last):', '  File ""C:\\Users\\Selene\\miniconda3\\lib\\site-packages\\IPython\\core\\interactiveshell.py"", line 3444, in run_code', '    exec(code_obj, self.user_global_ns, self.user_ns)', '  File ""C:\\Users\\Selene\\AppData\\Local\\Temp/ipykernel_21792/3759785821.py"", line 1, in <module>', '    data8', ""NameError: name 'data8' is not defined""]"
29,TypeError,'int' object is not callable,0,,2022-02-17 15:46:48.110005,"[('3(2)', 1)]","['Traceback (most recent call last):', '  File ""C:\\Users\\Selene\\miniconda3\\lib\\site-packages\\IPython\\core\\interactiveshell.py"", line 3444, in run_code', '    exec(code_obj, self.user_global_ns, self.user_ns)', '  File ""C:\\Users\\Selene\\AppData\\Local\\Temp/ipykernel_32476/305253956.py"", line 1, in <module>', '    3(2)', ""TypeError: 'int' object is not callable""]"
30,AttributeError,'NoneType' object has no attribute 'hello',0,,2022-02-17 15:47:03.749209,"[('a.hello', 2)]","['Traceback (most recent call last):', '  File ""C:\\Users\\Selene\\miniconda3\\lib\\site-packages\\IPython\\core\\interactiveshell.py"", line 3444, in run_code', '    exec(code_obj, self.user_global_ns, self.user_ns)', '  File ""C:\\Users\\Selene\\AppData\\Local\\Temp/ipykernel_32476/2399003099.py"", line 2, in <module>', '    a.hello', ""AttributeError: 'NoneType' object has no attribute 'hello'""]"
31,TypeError,'int' object is not callable,0,,2022-02-17 15:49:53.699066,"[('3(2)', 1)]","['Traceback (most recent call last):', '  File ""C:\\Users\\Selene\\miniconda3\\lib\\site-packages\\IPython\\core\\interactiveshell.py"", line 3444, in run_code', '    exec(code_obj, self.user_global_ns, self.user_ns)', '  File ""C:\\Users\\Selene\\AppData\\Local\\Temp/ipykernel_25196/305253956.py"", line 1, in <module>', '    3(2)', ""TypeError: 'int' object is not callable""]"
32,AttributeError,'NoneType' object has no attribute 'hello',0,,2022-02-17 15:50:09.219277,"[('a.hello', 2)]","['Traceback (most recent call last):', '  File ""C:\\Users\\Selene\\miniconda3\\lib\\site-packages\\IPython\\core\\interactiveshell.py"", line 3444, in run_code', '    exec(code_obj, self.user_global_ns, self.user_ns)', '  File ""C:\\Users\\Selene\\AppData\\Local\\Temp/ipykernel_25196/2399003099.py"", line 2, in <module>', '    a.hello', ""AttributeError: 'NoneType' object has no attribute 'hello'""]"
33,TypeError,'int' object is not callable,0,,2022-02-17 15:50:23.493008,"[('3(2)', 1)]","['Traceback (most recent call last):', '  File ""C:\\Users\\Selene\\miniconda3\\lib\\site-packages\\IPython\\core\\interactiveshell.py"", line 3444, in run_code', '    exec(code_obj, self.user_global_ns, self.user_ns)', '  File ""C:\\Users\\Selene\\AppData\\Local\\Temp/ipykernel_32936/305253956.py"", line 1, in <module>', '    3(2)', ""TypeError: 'int' object is not callable""]"
34,TypeError,'int' object is not callable,0,,2022-02-17 15:50:38.494492,"[('3(2)', 1)]","['Traceback (most recent call last):', '  File ""C:\\Users\\Selene\\miniconda3\\lib\\site-packages\\IPython\\core\\interactiveshell.py"", line 3444, in run_code', '    exec(code_obj, self.user_global_ns, self.user_ns)', '  File ""C:\\Users\\Selene\\AppData\\Local\\Temp/ipykernel_33068/305253956.py"", line 1, in <module>', '    3(2)', ""TypeError: 'int' object is not callable""]"
35,AttributeError,'NoneType' object has no attribute 'hello',0,,2022-02-17 15:50:57.450012,"[('a.hello', 2)]","['Traceback (most recent call last):', '  File ""C:\\Users\\Selene\\miniconda3\\lib\\site-packages\\IPython\\core\\interactiveshell.py"", line 3444, in run_code', '    exec(code_obj, self.user_global_ns, self.user_ns)', '  File ""C:\\Users\\Selene\\AppData\\Local\\Temp/ipykernel_33068/2399003099.py"", line 2, in <module>', '    a.hello', ""AttributeError: 'NoneType' object has no attribute 'hello'""]"
36,NameError,name 'data8' is not defined,0,,2022-02-17 15:51:22.449428,"[('data8', 1)]","['Traceback (most recent call last):', '  File ""C:\\Users\\Selene\\miniconda3\\lib\\site-packages\\IPython\\core\\interactiveshell.py"", line 3444, in run_code', '    exec(code_obj, self.user_global_ns, self.user_ns)', '  File ""C:\\Users\\Selene\\AppData\\Local\\Temp/ipykernel_33068/3759785821.py"", line 1, in <module>', '    data8', ""NameError: name 'data8' is not defined""]"
37,SyntaxError,"invalid syntax (Temp/ipykernel_33068/1866965863.py, line 1)",0,,2022-02-17 15:51:37.344710,"[('return compile(source, filename, symbol, self.flags | PyCF_ONLY_AST, 1)', 101)]","['Traceback (most recent call last):', '  File ""C:\\Users\\Selene\\miniconda3\\lib\\site-packages\\IPython\\core\\interactiveshell.py"", line 3143, in run_cell_async', '    code_ast = compiler.ast_parse(cell, filename=cell_name)', '  File ""C:\\Users\\Selene\\miniconda3\\lib\\site-packages\\IPython\\core\\compilerop.py"", line 101, in ast_parse', '    return compile(source, filename, symbol, self.flags | PyCF_ONLY_AST, 1)', '  File ""C:\\Users\\Selene\\AppData\\Local\\Temp/ipykernel_33068/1866965863.py"", line 1', '    2a', '     ^', 'SyntaxError: invalid syntax']"
38,TypeError,'int' object is not callable,0,,2022-02-18 23:47:41.446968,"[('3(2)', 1)]","['Traceback (most recent call last):', '  File ""C:\\Users\\Selene\\miniconda3\\lib\\site-packages\\IPython\\core\\interactiveshell.py"", line 3444, in run_code', '    exec(code_obj, self.user_global_ns, self.user_ns)', '  File ""C:\\Users\\Selene\\AppData\\Local\\Temp/ipykernel_40904/305253956.py"", line 1, in <module>', '    3(2)', ""TypeError: 'int' object is not callable""]"
39,AttributeError,'NoneType' object has no attribute 'hello',0,,2022-02-18 23:47:45.309333,"[('a.hello', 2)]","['Traceback (most recent call last):', '  File ""C:\\Users\\Selene\\miniconda3\\lib\\site-packages\\IPython\\core\\interactiveshell.py"", line 3444, in run_code', '    exec(code_obj, self.user_global_ns, self.user_ns)', '  File ""C:\\Users\\Selene\\AppData\\Local\\Temp/ipykernel_40904/2399003099.py"", line 2, in <module>', '    a.hello', ""AttributeError: 'NoneType' object has no attribute 'hello'""]"
40,TypeError,'int' object is not callable,0,,2022-02-18 23:49:15.582715,"[('3(2)', 1)]","['Traceback (most recent call last):', '  File ""C:\\Users\\Selene\\miniconda3\\lib\\site-packages\\IPython\\core\\interactiveshell.py"", line 3444, in run_code', '    exec(code_obj, self.user_global_ns, self.user_ns)', '  File ""C:\\Users\\Selene\\AppData\\Local\\Temp/ipykernel_36484/305253956.py"", line 1, in <module>', '    3(2)', ""TypeError: 'int' object is not callable""]"
41,TypeError,'int' object is not callable,0,,2022-02-18 23:49:41.540980,"[('3(2)', 1)]","['Traceback (most recent call last):', '  File ""C:\\Users\\Selene\\miniconda3\\lib\\site-packages\\IPython\\core\\interactiveshell.py"", line 3444, in run_code', '    exec(code_obj, self.user_global_ns, self.user_ns)', '  File ""C:\\Users\\Selene\\AppData\\Local\\Temp/ipykernel_39376/305253956.py"", line 1, in <module>', '    3(2)', ""TypeError: 'int' object is not callable""]"
42,TypeError,'int' object is not callable,0,,2022-02-18 23:52:56.972252,"[('3(2)', 1)]","['Traceback (most recent call last):', '  File ""C:\\Users\\Selene\\miniconda3\\lib\\site-packages\\IPython\\core\\interactiveshell.py"", line 3444, in run_code', '    exec(code_obj, self.user_global_ns, self.user_ns)', '  File ""C:\\Users\\Selene\\AppData\\Local\\Temp/ipykernel_2732/305253956.py"", line 1, in <module>', '    3(2)', ""TypeError: 'int' object is not callable""]"
43,TypeError,'int' object is not callable,0,,2022-02-18 23:54:16.141557,"[('3(2)', 1)]","['Traceback (most recent call last):', '  File ""C:\\Users\\Selene\\miniconda3\\lib\\site-packages\\IPython\\core\\interactiveshell.py"", line 3444, in run_code', '    exec(code_obj, self.user_global_ns, self.user_ns)', '  File ""C:\\Users\\Selene\\AppData\\Local\\Temp/ipykernel_37960/305253956.py"", line 1, in <module>', '    3(2)', ""TypeError: 'int' object is not callable""]"
44,TypeError,'int' object is not callable,0,,2022-02-18 23:54:38.756428,"[('3(2)', 1)]","['Traceback (most recent call last):', '  File ""C:\\Users\\Selene\\miniconda3\\lib\\site-packages\\IPython\\core\\interactiveshell.py"", line 3444, in run_code', '    exec(code_obj, self.user_global_ns, self.user_ns)', '  File ""C:\\Users\\Selene\\AppData\\Local\\Temp/ipykernel_39488/305253956.py"", line 1, in <module>', '    3(2)', ""TypeError: 'int' object is not callable""]"
45,TypeError,'int' object is not callable,0,,2022-02-18 23:55:08.454914,"[('3(2)', 1)]","['Traceback (most recent call last):', '  File ""C:\\Users\\Selene\\miniconda3\\lib\\site-packages\\IPython\\core\\interactiveshell.py"", line 3444, in run_code', '    exec(code_obj, self.user_global_ns, self.user_ns)', '  File ""C:\\Users\\Selene\\AppData\\Local\\Temp/ipykernel_36528/305253956.py"", line 1, in <module>', '    3(2)', ""TypeError: 'int' object is not callable""]"
46,TypeError,'int' object is not callable,0,,2022-02-18 23:59:01.074326,"[('3(2)', 1)]","['Traceback (most recent call last):', '  File ""C:\\Users\\Selene\\miniconda3\\lib\\site-packages\\IPython\\core\\interactiveshell.py"", line 3444, in run_code', '    exec(code_obj, self.user_global_ns, self.user_ns)', '  File ""C:\\Users\\Selene\\AppData\\Local\\Temp/ipykernel_12732/305253956.py"", line 1, in <module>', '    3(2)', ""TypeError: 'int' object is not callable""]"
47,TypeError,'int' object is not callable,0,,2022-02-18 23:59:32.492013,"[('3(2)', 1)]","['Traceback (most recent call last):', '  File ""C:\\Users\\Selene\\miniconda3\\lib\\site-packages\\IPython\\core\\interactiveshell.py"", line 3444, in run_code', '    exec(code_obj, self.user_global_ns, self.user_ns)', '  File ""C:\\Users\\Selene\\AppData\\Local\\Temp/ipykernel_41496/305253956.py"", line 1, in <module>', '    3(2)', ""TypeError: 'int' object is not callable""]"
48,TypeError,'int' object is not callable,0,,2022-02-19 00:05:34.036639,"[('3(2)', 1)]","['Traceback (most recent call last):', '  File ""C:\\Users\\Selene\\miniconda3\\lib\\site-packages\\IPython\\core\\interactiveshell.py"", line 3444, in run_code', '    exec(code_obj, self.user_global_ns, self.user_ns)', '  File ""C:\\Users\\Selene\\AppData\\Local\\Temp/ipykernel_41784/305253956.py"", line 1, in <module>', '    3(2)', ""TypeError: 'int' object is not callable""]"
49,TypeError,'int' object is not callable,0,,2022-02-19 00:06:16.851554,"[('3(2)', 1)]","['Traceback (most recent call last):', '  File ""C:\\Users\\Selene\\miniconda3\\lib\\site-packages\\IPython\\core\\interactiveshell.py"", line 3444, in run_code', '    exec(code_obj, self.user_global_ns, self.user_ns)', '  File ""C:\\Users\\Selene\\AppData\\Local\\Temp/ipykernel_36008/305253956.py"", line 1, in <module>', '    3(2)', ""TypeError: 'int' object is not callable""]"
50,TypeError,'int' object is not callable,0,,2022-02-19 00:06:24.682482,"[('3(2)', 1)]","['Traceback (most recent call last):', '  File ""C:\\Users\\Selene\\miniconda3\\lib\\site-packages\\IPython\\core\\interactiveshell.py"", line 3444, in run_code', '    exec(code_obj, self.user_global_ns, self.user_ns)', '  File ""C:\\Users\\Selene\\AppData\\Local\\Temp/ipykernel_33192/305253956.py"", line 1, in <module>', '    3(2)', ""TypeError: 'int' object is not callable""]"
51,TypeError,'int' object is not callable,0,,2022-02-19 00:07:08.262269,"[('3(2)', 1)]","['Traceback (most recent call last):', '  File ""C:\\Users\\Selene\\miniconda3\\lib\\site-packages\\IPython\\core\\interactiveshell.py"", line 3444, in run_code', '    exec(code_obj, self.user_global_ns, self.user_ns)', '  File ""C:\\Users\\Selene\\AppData\\Local\\Temp/ipykernel_40772/305253956.py"", line 1, in <module>', '    3(2)', ""TypeError: 'int' object is not callable""]"
52,TypeError,'int' object is not callable,0,,2022-02-19 00:07:24.872721,"[('3(2)', 1)]","['Traceback (most recent call last):', '  File ""C:\\Users\\Selene\\miniconda3\\lib\\site-packages\\IPython\\core\\interactiveshell.py"", line 3444, in run_code', '    exec(code_obj, self.user_global_ns, self.user_ns)', '  File ""C:\\Users\\Selene\\AppData\\Local\\Temp/ipykernel_39956/305253956.py"", line 1, in <module>', '    3(2)', ""TypeError: 'int' object is not callable""]"
53,TypeError,'int' object is not callable,0,,2022-02-19 00:14:54.742269,"[('3(2)', 1)]","['Traceback (most recent call last):', '  File ""C:\\Users\\Selene\\miniconda3\\lib\\site-packages\\IPython\\core\\interactiveshell.py"", line 3444, in run_code', '    exec(code_obj, self.user_global_ns, self.user_ns)', '  File ""C:\\Users\\Selene\\AppData\\Local\\Temp/ipykernel_39684/305253956.py"", line 1, in <module>', '    3(2)', ""TypeError: 'int' object is not callable""]"
54,TypeError,'int' object is not callable,0,,2022-02-19 19:07:41.565070,"[('3(2)', 1)]","['Traceback (most recent call last):', '  File ""C:\\Users\\Selene\\miniconda3\\lib\\site-packages\\IPython\\core\\interactiveshell.py"", line 3444, in run_code', '    exec(code_obj, self.user_global_ns, self.user_ns)', '  File ""C:\\Users\\Selene\\AppData\\Local\\Temp/ipykernel_20356/305253956.py"", line 1, in <module>', '    3(2)', ""TypeError: 'int' object is not callable""]"
55,IndexError,list index out of range,0,,2022-02-19 19:08:31.678593,"[('[2][1]', 1)]","['Traceback (most recent call last):', '  File ""C:\\Users\\Selene\\miniconda3\\lib\\site-packages\\IPython\\core\\interactiveshell.py"", line 3444, in run_code', '    exec(code_obj, self.user_global_ns, self.user_ns)', '  File ""C:\\Users\\Selene\\AppData\\Local\\Temp/ipykernel_20356/1686336973.py"", line 1, in <module>', '    [2][1]', 'IndexError: list index out of range']"
56,NameError,name 'h' is not defined,0,,2022-02-19 19:08:40.825568,"[('print(h)', 1)]","['Traceback (most recent call last):', '  File ""C:\\Users\\Selene\\miniconda3\\lib\\site-packages\\IPython\\core\\interactiveshell.py"", line 3444, in run_code', '    exec(code_obj, self.user_global_ns, self.user_ns)', '  File ""C:\\Users\\Selene\\AppData\\Local\\Temp/ipykernel_20356/259929948.py"", line 1, in <module>', '    print(h)', ""NameError: name 'h' is not defined""]"
57,TypeError,'int' object is not callable,0,,2022-02-19 19:11:27.160536
58,AttributeError,'NoneType' object has no attribute 'hello',0,,2022-02-19 19:11:27.403574
59,NameError,name 'data8' is not defined,0,,2022-02-19 19:11:27.594232
60,SyntaxError,"invalid syntax (Temp/ipykernel_36276/1866965863.py, line 1)",0,,2022-02-19 19:11:27.915990
61,AttributeError,module 'numpy' has no attribute 'aragne',0,,2022-02-19 19:11:28.186280
62,IndexError,list index out of range,0,,2022-02-19 19:11:28.417737
63,AttributeError,module 'numpy' has no attribute 'hi',0,,2022-02-19 19:11:28.660628
64,NameError,name 'Table' is not defined,0,,2022-02-19 19:11:28.889823
65,ValueError,invalid literal for int() with base 10: 'HI',0,,2022-02-19 19:11:29.145818
66,TypeError,'int' object is not callable,0,,2022-02-24 02:18:53.624066
67,AttributeError,'NoneType' object has no attribute 'hello',0,,2022-02-24 02:19:50.166426
68,AttributeError,module 'numpy' has no attribute 'hi',0,,2022-02-24 02:26:15.461521
69,TypeError,'int' object is not callable,0,,2022-02-24 15:12:07.513686,"[('3(2)', 2)]","['Traceback (most recent call last):', '  File ""C:\\Users\\Selene\\miniconda3\\lib\\site-packages\\IPython\\core\\interactiveshell.py"", line 3444, in run_code', '    exec(code_obj, self.user_global_ns, self.user_ns)', '  File ""C:\\Users\\Selene\\AppData\\Local\\Temp/ipykernel_32168/1418619884.py"", line 2, in <module>', '    3(2)', ""TypeError: 'int' object is not callable""]"
70,AttributeError,'NoneType' object has no attribute 'hello',0,,2022-02-24 15:12:08.640301,"[('a.hello', 2)]","['Traceback (most recent call last):', '  File ""C:\\Users\\Selene\\miniconda3\\lib\\site-packages\\IPython\\core\\interactiveshell.py"", line 3444, in run_code', '    exec(code_obj, self.user_global_ns, self.user_ns)', '  File ""C:\\Users\\Selene\\AppData\\Local\\Temp/ipykernel_32168/2399003099.py"", line 2, in <module>', '    a.hello', ""AttributeError: 'NoneType' object has no attribute 'hello'""]"
71,NameError,name 'data8' is not defined,0,,2022-02-24 15:12:09.426103,"[('data8', 15)]","['Traceback (most recent call last):', '  File ""C:\\Users\\Selene\\miniconda3\\lib\\site-packages\\IPython\\core\\interactiveshell.py"", line 3444, in run_code', '    exec(code_obj, self.user_global_ns, self.user_ns)', '  File ""C:\\Users\\Selene\\AppData\\Local\\Temp/ipykernel_32168/4159590661.py"", line 15, in <module>', '    data8', ""NameError: name 'data8' is not defined""]"
72,SyntaxError,"invalid syntax (Temp/ipykernel_32168/1866965863.py, line 1)",0,,2022-02-24 15:12:10.056581,"[('return compile(source, filename, symbol, self.flags | PyCF_ONLY_AST, 1)', 101)]","['Traceback (most recent call last):', '  File ""C:\\Users\\Selene\\miniconda3\\lib\\site-packages\\IPython\\core\\interactiveshell.py"", line 3143, in run_cell_async', '    code_ast = compiler.ast_parse(cell, filename=cell_name)', '  File ""C:\\Users\\Selene\\miniconda3\\lib\\site-packages\\IPython\\core\\compilerop.py"", line 101, in ast_parse', '    return compile(source, filename, symbol, self.flags | PyCF_ONLY_AST, 1)', '  File ""C:\\Users\\Selene\\AppData\\Local\\Temp/ipykernel_32168/1866965863.py"", line 1', '    2a', '     ^', 'SyntaxError: invalid syntax']"
73,AttributeError,module 'numpy' has no attribute 'aragne',0,,2022-02-24 15:12:10.902820,"[(""np.aragne('HI')"", 1), ('raise AttributeError(""module {!r} has no attribute ""', 313)]","['Traceback (most recent call last):', '  File ""C:\\Users\\Selene\\miniconda3\\lib\\site-packages\\IPython\\core\\interactiveshell.py"", line 3444, in run_code', '    exec(code_obj, self.user_global_ns, self.user_ns)', '  File ""C:\\Users\\Selene\\AppData\\Local\\Temp/ipykernel_32168/1147446779.py"", line 1, in <module>', ""    np.aragne('HI')"", '  File ""C:\\Users\\Selene\\miniconda3\\lib\\site-packages\\numpy\\__init__.py"", line 313, in __getattr__', '    raise AttributeError(""module {!r} has no attribute ""', ""AttributeError: module 'numpy' has no attribute 'aragne'""]"
74,IndexError,list index out of range,0,,2022-02-24 15:12:11.325557,"[('[2][1]', 1)]","['Traceback (most recent call last):', '  File ""C:\\Users\\Selene\\miniconda3\\lib\\site-packages\\IPython\\core\\interactiveshell.py"", line 3444, in run_code', '    exec(code_obj, self.user_global_ns, self.user_ns)', '  File ""C:\\Users\\Selene\\AppData\\Local\\Temp/ipykernel_32168/1686336973.py"", line 1, in <module>', '    [2][1]', 'IndexError: list index out of range']"
75,AttributeError,module 'numpy' has no attribute 'hi',0,,2022-02-24 15:12:11.789429,"[('np.hi', 1), ('raise AttributeError(""module {!r} has no attribute ""', 313)]","['Traceback (most recent call last):', '  File ""C:\\Users\\Selene\\miniconda3\\lib\\site-packages\\IPython\\core\\interactiveshell.py"", line 3444, in run_code', '    exec(code_obj, self.user_global_ns, self.user_ns)', '  File ""C:\\Users\\Selene\\AppData\\Local\\Temp/ipykernel_32168/1570163000.py"", line 1, in <module>', '    np.hi', '  File ""C:\\Users\\Selene\\miniconda3\\lib\\site-packages\\numpy\\__init__.py"", line 313, in __getattr__', '    raise AttributeError(""module {!r} has no attribute ""', ""AttributeError: module 'numpy' has no attribute 'hi'""]"
76,NameError,name 'Table' is not defined,0,,2022-02-24 15:12:12.204870,"[('Table()', 1)]","['Traceback (most recent call last):', '  File ""C:\\Users\\Selene\\miniconda3\\lib\\site-packages\\IPython\\core\\interactiveshell.py"", line 3444, in run_code', '    exec(code_obj, self.user_global_ns, self.user_ns)', '  File ""C:\\Users\\Selene\\AppData\\Local\\Temp/ipykernel_32168/4234517321.py"", line 1, in <module>', '    Table()', ""NameError: name 'Table' is not defined""]"
77,ValueError,invalid literal for int() with base 10: 'HI',0,,2022-02-24 15:12:12.545406,"[('int(""HI"")', 1)]","['Traceback (most recent call last):', '  File ""C:\\Users\\Selene\\miniconda3\\lib\\site-packages\\IPython\\core\\interactiveshell.py"", line 3444, in run_code', '    exec(code_obj, self.user_global_ns, self.user_ns)', '  File ""C:\\Users\\Selene\\AppData\\Local\\Temp/ipykernel_32168/532684827.py"", line 1, in <module>', '    int(""HI"")', ""ValueError: invalid literal for int() with base 10: 'HI'""]"
78,ZeroDivisionError,division by zero,0,,2022-02-24 15:12:12.858264,"[('f()', 4), ('3 / 0', 2)]","['Traceback (most recent call last):', '  File ""C:\\Users\\Selene\\miniconda3\\lib\\site-packages\\IPython\\core\\interactiveshell.py"", line 3444, in run_code', '    exec(code_obj, self.user_global_ns, self.user_ns)', '  File ""C:\\Users\\Selene\\AppData\\Local\\Temp/ipykernel_32168/2851013969.py"", line 4, in <module>', '    f()', '  File ""C:\\Users\\Selene\\AppData\\Local\\Temp/ipykernel_32168/2851013969.py"", line 2, in f', '    3 / 0', 'ZeroDivisionError: division by zero']"
79,ZeroDivisionError,division by zero,0,,2022-02-24 15:12:13.373746,"[('f()', 1), ('3 / 0', 2)]","['Traceback (most recent call last):', '  File ""C:\\Users\\Selene\\miniconda3\\lib\\site-packages\\IPython\\core\\interactiveshell.py"", line 3444, in run_code', '    exec(code_obj, self.user_global_ns, self.user_ns)', '  File ""C:\\Users\\Selene\\AppData\\Local\\Temp/ipykernel_32168/3782956317.py"", line 1, in <module>', '    f()', '  File ""C:\\Users\\Selene\\AppData\\Local\\Temp/ipykernel_32168/2851013969.py"", line 2, in f', '    3 / 0', 'ZeroDivisionError: division by zero']"
80,AttributeError,'NoneType' object has no attribute 'hello',0,,2022-02-24 15:12:20.767221,"[('a.hello', 2)]","['Traceback (most recent call last):', '  File ""C:\\Users\\Selene\\miniconda3\\lib\\site-packages\\IPython\\core\\interactiveshell.py"", line 3444, in run_code', '    exec(code_obj, self.user_global_ns, self.user_ns)', '  File ""C:\\Users\\Selene\\AppData\\Local\\Temp/ipykernel_32168/2399003099.py"", line 2, in <module>', '    a.hello', ""AttributeError: 'NoneType' object has no attribute 'hello'""]"
81,SyntaxError,"invalid syntax (Temp/ipykernel_32168/1866965863.py, line 1)",0,,2022-02-24 15:12:45.371250,"[('return compile(source, filename, symbol, self.flags | PyCF_ONLY_AST, 1)', 101)]","['Traceback (most recent call last):', '  File ""C:\\Users\\Selene\\miniconda3\\lib\\site-packages\\IPython\\core\\interactiveshell.py"", line 3143, in run_cell_async', '    code_ast = compiler.ast_parse(cell, filename=cell_name)', '  File ""C:\\Users\\Selene\\miniconda3\\lib\\site-packages\\IPython\\core\\compilerop.py"", line 101, in ast_parse', '    return compile(source, filename, symbol, self.flags | PyCF_ONLY_AST, 1)', '  File ""C:\\Users\\Selene\\AppData\\Local\\Temp/ipykernel_32168/1866965863.py"", line 1', '    2a', '     ^', 'SyntaxError: invalid syntax']"
82,AttributeError,module 'numpy' has no attribute 'aragne',0,,2022-02-24 15:12:54.321026,"[(""np.aragne('HI')"", 1), ('raise AttributeError(""module {!r} has no attribute ""', 313)]","['Traceback (most recent call last):', '  File ""C:\\Users\\Selene\\miniconda3\\lib\\site-packages\\IPython\\core\\interactiveshell.py"", line 3444, in run_code', '    exec(code_obj, self.user_global_ns, self.user_ns)', '  File ""C:\\Users\\Selene\\AppData\\Local\\Temp/ipykernel_32168/1147446779.py"", line 1, in <module>', ""    np.aragne('HI')"", '  File ""C:\\Users\\Selene\\miniconda3\\lib\\site-packages\\numpy\\__init__.py"", line 313, in __getattr__', '    raise AttributeError(""module {!r} has no attribute ""', ""AttributeError: module 'numpy' has no attribute 'aragne'""]"
83,ModuleNotFoundError,No module named 'wut',0,,2022-02-24 15:13:15.342642,"[(""get_ipython().run_line_magic('load_ext', 'wut')"", 5), ('result = fn(*args, **kwargs)', 2351)]","['Traceback (most recent call last):', '  File ""C:\\Users\\Selene\\miniconda3\\lib\\site-packages\\IPython\\core\\interactiveshell.py"", line 3444, in run_code', '    exec(code_obj, self.user_global_ns, self.user_ns)', '  File ""C:\\Users\\Selene\\AppData\\Local\\Temp/ipykernel_32168/2030035837.py"", line 5, in <module>', ""    get_ipython().run_line_magic('load_ext', 'wut')"", '  File ""C:\\Users\\Selene\\miniconda3\\lib\\site-packages\\IPython\\core\\interactiveshell.py"", line 2351, in run_line_magic', '    result = fn(*args, **kwargs)', '  File ""C:\\Users\\Selene\\miniconda3\\lib\\site-packages\\decorator.py"", line 232, in fun', '    return caller(func, *(extras + args), **kw)', '  File ""C:\\Users\\Selene\\miniconda3\\lib\\site-packages\\IPython\\core\\magic.py"", line 187, in <lambda>', '    call = lambda f, *a, **k: f(*a, **k)', '  File ""C:\\Users\\Selene\\miniconda3\\lib\\site-packages\\IPython\\core\\magics\\extension.py"", line 33, in load_ext', '    res = self.shell.extension_manager.load_extension(module_str)', '  File ""C:\\Users\\Selene\\miniconda3\\lib\\site-packages\\IPython\\core\\extensions.py"", line 80, in load_extension', '    mod = import_module(module_str)', '  File ""C:\\Users\\Selene\\miniconda3\\lib\\importlib\\__init__.py"", line 127, in import_module', '    return _bootstrap._gcd_import(name[level:], package, level)', '  File ""<frozen importlib._bootstrap>"", line 1030, in _gcd_import', '  File ""<frozen importlib._bootstrap>"", line 1007, in _find_and_load', '  File ""<frozen importlib._bootstrap>"", line 984, in _find_and_load_unlocked', ""ModuleNotFoundError: No module named 'wut'""]"
84,SyntaxError,"invalid syntax (Temp/ipykernel_32168/1866965863.py, line 1)",0,,2022-02-24 15:13:26.901271,"[('return compile(source, filename, symbol, self.flags | PyCF_ONLY_AST, 1)', 101)]","['Traceback (most recent call last):', '  File ""C:\\Users\\Selene\\miniconda3\\lib\\site-packages\\IPython\\core\\interactiveshell.py"", line 3143, in run_cell_async', '    code_ast = compiler.ast_parse(cell, filename=cell_name)', '  File ""C:\\Users\\Selene\\miniconda3\\lib\\site-packages\\IPython\\core\\compilerop.py"", line 101, in ast_parse', '    return compile(source, filename, symbol, self.flags | PyCF_ONLY_AST, 1)', '  File ""C:\\Users\\Selene\\AppData\\Local\\Temp/ipykernel_32168/1866965863.py"", line 1', '    2a', '     ^', 'SyntaxError: invalid syntax']"
85,SyntaxError,"invalid syntax (Temp/ipykernel_32168/1866965863.py, line 1)",0,,2022-02-24 15:13:38.225738,"[('return compile(source, filename, symbol, self.flags | PyCF_ONLY_AST, 1)', 101)]","['Traceback (most recent call last):', '  File ""C:\\Users\\Selene\\miniconda3\\lib\\site-packages\\IPython\\core\\interactiveshell.py"", line 3143, in run_cell_async', '    code_ast = compiler.ast_parse(cell, filename=cell_name)', '  File ""C:\\Users\\Selene\\miniconda3\\lib\\site-packages\\IPython\\core\\compilerop.py"", line 101, in ast_parse', '    return compile(source, filename, symbol, self.flags | PyCF_ONLY_AST, 1)', '  File ""C:\\Users\\Selene\\AppData\\Local\\Temp/ipykernel_32168/1866965863.py"", line 1', '    2a', '     ^', 'SyntaxError: invalid syntax']"
86,AttributeError,module 'numpy' has no attribute 'aragne',0,,2022-02-24 15:13:46.533721,"[(""np.aragne('HI')"", 1), ('raise AttributeError(""module {!r} has no attribute ""', 313)]","['Traceback (most recent call last):', '  File ""C:\\Users\\Selene\\miniconda3\\lib\\site-packages\\IPython\\core\\interactiveshell.py"", line 3444, in run_code', '    exec(code_obj, self.user_global_ns, self.user_ns)', '  File ""C:\\Users\\Selene\\AppData\\Local\\Temp/ipykernel_32168/1147446779.py"", line 1, in <module>', ""    np.aragne('HI')"", '  File ""C:\\Users\\Selene\\miniconda3\\lib\\site-packages\\numpy\\__init__.py"", line 313, in __getattr__', '    raise AttributeError(""module {!r} has no attribute ""', ""AttributeError: module 'numpy' has no attribute 'aragne'""]"
87,IndexError,list index out of range,0,,2022-02-24 15:14:00.026304,"[('[2][1]', 1)]","['Traceback (most recent call last):', '  File ""C:\\Users\\Selene\\miniconda3\\lib\\site-packages\\IPython\\core\\interactiveshell.py"", line 3444, in run_code', '    exec(code_obj, self.user_global_ns, self.user_ns)', '  File ""C:\\Users\\Selene\\AppData\\Local\\Temp/ipykernel_32168/1686336973.py"", line 1, in <module>', '    [2][1]', 'IndexError: list index out of range']"
88,ValueError,"'wut' was not found in history, as a file, url, nor in the user namespace.",0,,2022-03-03 14:54:16.379101,"[(""get_ipython().run_line_magic('load', 'wut')"", 5), ('result = fn(*args, **kwargs)', 2351)]","['Traceback (most recent call last):', '  File ""C:\\Users\\Selene\\miniconda3\\lib\\site-packages\\IPython\\core\\interactiveshell.py"", line 3764, in find_user_code', '    codeobj = eval(target, self.user_ns)', '  File ""<string>"", line 1, in <module>', ""NameError: name 'wut' is not defined"", '', 'During handling of the above exception, another exception occurred:', '', 'Traceback (most recent call last):', '  File ""C:\\Users\\Selene\\miniconda3\\lib\\site-packages\\IPython\\core\\interactiveshell.py"", line 3444, in run_code', '    exec(code_obj, self.user_global_ns, self.user_ns)', '  File ""C:\\Users\\Selene\\AppData\\Local\\Temp/ipykernel_44868/191052120.py"", line 5, in <module>', ""    get_ipython().run_line_magic('load', 'wut')"", '  File ""C:\\Users\\Selene\\miniconda3\\lib\\site-packages\\IPython\\core\\interactiveshell.py"", line 2351, in run_line_magic', '    result = fn(*args, **kwargs)', '  File ""C:\\Users\\Selene\\miniconda3\\lib\\site-packages\\decorator.py"", line 232, in fun', '    return caller(func, *(extras + args), **kw)', '  File ""C:\\Users\\Selene\\miniconda3\\lib\\site-packages\\IPython\\core\\magic.py"", line 187, in <lambda>', '    call = lambda f, *a, **k: f(*a, **k)', '  File ""C:\\Users\\Selene\\miniconda3\\lib\\site-packages\\IPython\\core\\magics\\code.py"", line 353, in load', '    contents = self.shell.find_user_code(args, search_ns=search_ns)', '  File ""C:\\Users\\Selene\\miniconda3\\lib\\site-packages\\IPython\\core\\interactiveshell.py"", line 3766, in find_user_code', '    raise ValueError((""\'%s\' was not found in history, as a file, url, ""', ""ValueError: 'wut' was not found in history, as a file, url, nor in the user namespace.""]"
89,ModuleNotFoundError,No module named 'wut',0,,2022-03-03 14:54:42.981091,"[(""get_ipython().run_line_magic('load_ext', 'wut')"", 5), ('result = fn(*args, **kwargs)', 2351)]","['Traceback (most recent call last):', '  File ""C:\\Users\\Selene\\miniconda3\\lib\\site-packages\\IPython\\core\\interactiveshell.py"", line 3444, in run_code', '    exec(code_obj, self.user_global_ns, self.user_ns)', '  File ""C:\\Users\\Selene\\AppData\\Local\\Temp/ipykernel_44868/2030035837.py"", line 5, in <module>', ""    get_ipython().run_line_magic('load_ext', 'wut')"", '  File ""C:\\Users\\Selene\\miniconda3\\lib\\site-packages\\IPython\\core\\interactiveshell.py"", line 2351, in run_line_magic', '    result = fn(*args, **kwargs)', '  File ""C:\\Users\\Selene\\miniconda3\\lib\\site-packages\\decorator.py"", line 232, in fun', '    return caller(func, *(extras + args), **kw)', '  File ""C:\\Users\\Selene\\miniconda3\\lib\\site-packages\\IPython\\core\\magic.py"", line 187, in <lambda>', '    call = lambda f, *a, **k: f(*a, **k)', '  File ""C:\\Users\\Selene\\miniconda3\\lib\\site-packages\\IPython\\core\\magics\\extension.py"", line 33, in load_ext', '    res = self.shell.extension_manager.load_extension(module_str)', '  File ""C:\\Users\\Selene\\miniconda3\\lib\\site-packages\\IPython\\core\\extensions.py"", line 80, in load_extension', '    mod = import_module(module_str)', '  File ""C:\\Users\\Selene\\miniconda3\\lib\\importlib\\__init__.py"", line 127, in import_module', '    return _bootstrap._gcd_import(name[level:], package, level)', '  File ""<frozen importlib._bootstrap>"", line 1030, in _gcd_import', '  File ""<frozen importlib._bootstrap>"", line 1007, in _find_and_load', '  File ""<frozen importlib._bootstrap>"", line 984, in _find_and_load_unlocked', ""ModuleNotFoundError: No module named 'wut'""]"
90,SyntaxError,"invalid syntax (Temp/ipykernel_44868/4242947851.py, line 5)",0,,2022-03-03 14:55:02.185430,"[('return compile(source, filename, symbol, self.flags | PyCF_ONLY_AST, 1)', 101)]","['Traceback (most recent call last):', '  File ""C:\\Users\\Selene\\miniconda3\\lib\\site-packages\\IPython\\core\\interactiveshell.py"", line 3143, in run_cell_async', '    code_ast = compiler.ast_parse(cell, filename=cell_name)', '  File ""C:\\Users\\Selene\\miniconda3\\lib\\site-packages\\IPython\\core\\compilerop.py"", line 101, in ast_parse', '    return compile(source, filename, symbol, self.flags | PyCF_ONLY_AST, 1)', '  File ""C:\\Users\\Selene\\AppData\\Local\\Temp/ipykernel_44868/4242947851.py"", line 5', '    pip install wut', '        ^', 'SyntaxError: invalid syntax']"
91,ModuleNotFoundError,No module named 'wut',0,,2022-03-03 14:55:21.324385,"[(""get_ipython().run_line_magic('load_ext', 'wut')"", 6), ('result = fn(*args, **kwargs)', 2351)]","['Traceback (most recent call last):', '  File ""C:\\Users\\Selene\\miniconda3\\lib\\site-packages\\IPython\\core\\interactiveshell.py"", line 3444, in run_code', '    exec(code_obj, self.user_global_ns, self.user_ns)', '  File ""C:\\Users\\Selene\\AppData\\Local\\Temp/ipykernel_48820/2710398046.py"", line 6, in <module>', ""    get_ipython().run_line_magic('load_ext', 'wut')"", '  File ""C:\\Users\\Selene\\miniconda3\\lib\\site-packages\\IPython\\core\\interactiveshell.py"", line 2351, in run_line_magic', '    result = fn(*args, **kwargs)', '  File ""C:\\Users\\Selene\\miniconda3\\lib\\site-packages\\decorator.py"", line 232, in fun', '    return caller(func, *(extras + args), **kw)', '  File ""C:\\Users\\Selene\\miniconda3\\lib\\site-packages\\IPython\\core\\magic.py"", line 187, in <lambda>', '    call = lambda f, *a, **k: f(*a, **k)', '  File ""C:\\Users\\Selene\\miniconda3\\lib\\site-packages\\IPython\\core\\magics\\extension.py"", line 33, in load_ext', '    res = self.shell.extension_manager.load_extension(module_str)', '  File ""C:\\Users\\Selene\\miniconda3\\lib\\site-packages\\IPython\\core\\extensions.py"", line 80, in load_extension', '    mod = import_module(module_str)', '  File ""C:\\Users\\Selene\\miniconda3\\lib\\importlib\\__init__.py"", line 127, in import_module', '    return _bootstrap._gcd_import(name[level:], package, level)', '  File ""<frozen importlib._bootstrap>"", line 1030, in _gcd_import', '  File ""<frozen importlib._bootstrap>"", line 1007, in _find_and_load', '  File ""<frozen importlib._bootstrap>"", line 984, in _find_and_load_unlocked', ""ModuleNotFoundError: No module named 'wut'""]"
92,ModuleNotFoundError,No module named 'wut',0,,2022-03-03 14:55:40.525645,"[(""get_ipython().run_line_magic('load_ext', 'wut')"", 5), ('result = fn(*args, **kwargs)', 2351)]","['Traceback (most recent call last):', '  File ""C:\\Users\\Selene\\miniconda3\\lib\\site-packages\\IPython\\core\\interactiveshell.py"", line 3444, in run_code', '    exec(code_obj, self.user_global_ns, self.user_ns)', '  File ""C:\\Users\\Selene\\AppData\\Local\\Temp/ipykernel_48820/2030035837.py"", line 5, in <module>', ""    get_ipython().run_line_magic('load_ext', 'wut')"", '  File ""C:\\Users\\Selene\\miniconda3\\lib\\site-packages\\IPython\\core\\interactiveshell.py"", line 2351, in run_line_magic', '    result = fn(*args, **kwargs)', '  File ""C:\\Users\\Selene\\miniconda3\\lib\\site-packages\\decorator.py"", line 232, in fun', '    return caller(func, *(extras + args), **kw)', '  File ""C:\\Users\\Selene\\miniconda3\\lib\\site-packages\\IPython\\core\\magic.py"", line 187, in <lambda>', '    call = lambda f, *a, **k: f(*a, **k)', '  File ""C:\\Users\\Selene\\miniconda3\\lib\\site-packages\\IPython\\core\\magics\\extension.py"", line 33, in load_ext', '    res = self.shell.extension_manager.load_extension(module_str)', '  File ""C:\\Users\\Selene\\miniconda3\\lib\\site-packages\\IPython\\core\\extensions.py"", line 80, in load_extension', '    mod = import_module(module_str)', '  File ""C:\\Users\\Selene\\miniconda3\\lib\\importlib\\__init__.py"", line 127, in import_module', '    return _bootstrap._gcd_import(name[level:], package, level)', '  File ""<frozen importlib._bootstrap>"", line 1030, in _gcd_import', '  File ""<frozen importlib._bootstrap>"", line 1007, in _find_and_load', '  File ""<frozen importlib._bootstrap>"", line 984, in _find_and_load_unlocked', ""ModuleNotFoundError: No module named 'wut'""]"
93,AttributeError,'NoneType' object has no attribute 'hello',0,,2022-03-03 14:56:01.223764,"[('a.hello', 2)]","['Traceback (most recent call last):', '  File ""C:\\Users\\Selene\\miniconda3\\lib\\site-packages\\IPython\\core\\interactiveshell.py"", line 3444, in run_code', '    exec(code_obj, self.user_global_ns, self.user_ns)', '  File ""C:\\Users\\Selene\\AppData\\Local\\Temp/ipykernel_48820/2399003099.py"", line 2, in <module>', '    a.hello', ""AttributeError: 'NoneType' object has no attribute 'hello'""]"
94,ModuleNotFoundError,No module named 'wut',0,,2022-03-03 14:56:17.070258,"[(""get_ipython().run_line_magic('load_ext', 'wut')"", 5), ('result = fn(*args, **kwargs)', 2351)]","['Traceback (most recent call last):', '  File ""C:\\Users\\Selene\\miniconda3\\lib\\site-packages\\IPython\\core\\interactiveshell.py"", line 3444, in run_code', '    exec(code_obj, self.user_global_ns, self.user_ns)', '  File ""C:\\Users\\Selene\\AppData\\Local\\Temp/ipykernel_48820/2030035837.py"", line 5, in <module>', ""    get_ipython().run_line_magic('load_ext', 'wut')"", '  File ""C:\\Users\\Selene\\miniconda3\\lib\\site-packages\\IPython\\core\\interactiveshell.py"", line 2351, in run_line_magic', '    result = fn(*args, **kwargs)', '  File ""C:\\Users\\Selene\\miniconda3\\lib\\site-packages\\decorator.py"", line 232, in fun', '    return caller(func, *(extras + args), **kw)', '  File ""C:\\Users\\Selene\\miniconda3\\lib\\site-packages\\IPython\\core\\magic.py"", line 187, in <lambda>', '    call = lambda f, *a, **k: f(*a, **k)', '  File ""C:\\Users\\Selene\\miniconda3\\lib\\site-packages\\IPython\\core\\magics\\extension.py"", line 33, in load_ext', '    res = self.shell.extension_manager.load_extension(module_str)', '  File ""C:\\Users\\Selene\\miniconda3\\lib\\site-packages\\IPython\\core\\extensions.py"", line 80, in load_extension', '    mod = import_module(module_str)', '  File ""C:\\Users\\Selene\\miniconda3\\lib\\importlib\\__init__.py"", line 127, in import_module', '    return _bootstrap._gcd_import(name[level:], package, level)', '  File ""<frozen importlib._bootstrap>"", line 1030, in _gcd_import', '  File ""<frozen importlib._bootstrap>"", line 1007, in _find_and_load', '  File ""<frozen importlib._bootstrap>"", line 984, in _find_and_load_unlocked', ""ModuleNotFoundError: No module named 'wut'""]"
95,ModuleNotFoundError,No module named 'wut',0,,2022-03-03 14:56:58.724676,"[(""get_ipython().run_line_magic('load_ext', 'wut')"", 5), ('result = fn(*args, **kwargs)', 2351)]","['Traceback (most recent call last):', '  File ""C:\\Users\\Selene\\miniconda3\\lib\\site-packages\\IPython\\core\\interactiveshell.py"", line 3444, in run_code', '    exec(code_obj, self.user_global_ns, self.user_ns)', '  File ""C:\\Users\\Selene\\AppData\\Local\\Temp/ipykernel_48820/2030035837.py"", line 5, in <module>', ""    get_ipython().run_line_magic('load_ext', 'wut')"", '  File ""C:\\Users\\Selene\\miniconda3\\lib\\site-packages\\IPython\\core\\interactiveshell.py"", line 2351, in run_line_magic', '    result = fn(*args, **kwargs)', '  File ""C:\\Users\\Selene\\miniconda3\\lib\\site-packages\\decorator.py"", line 232, in fun', '    return caller(func, *(extras + args), **kw)', '  File ""C:\\Users\\Selene\\miniconda3\\lib\\site-packages\\IPython\\core\\magic.py"", line 187, in <lambda>', '    call = lambda f, *a, **k: f(*a, **k)', '  File ""C:\\Users\\Selene\\miniconda3\\lib\\site-packages\\IPython\\core\\magics\\extension.py"", line 33, in load_ext', '    res = self.shell.extension_manager.load_extension(module_str)', '  File ""C:\\Users\\Selene\\miniconda3\\lib\\site-packages\\IPython\\core\\extensions.py"", line 80, in load_extension', '    mod = import_module(module_str)', '  File ""C:\\Users\\Selene\\miniconda3\\lib\\importlib\\__init__.py"", line 127, in import_module', '    return _bootstrap._gcd_import(name[level:], package, level)', '  File ""<frozen importlib._bootstrap>"", line 1030, in _gcd_import', '  File ""<frozen importlib._bootstrap>"", line 1007, in _find_and_load', '  File ""<frozen importlib._bootstrap>"", line 984, in _find_and_load_unlocked', ""ModuleNotFoundError: No module named 'wut'""]"
96,ModuleNotFoundError,No module named 'wut',0,,2022-03-03 14:57:01.691153,"[(""get_ipython().run_line_magic('load_ext', 'wut')"", 5), ('result = fn(*args, **kwargs)', 2351)]","['Traceback (most recent call last):', '  File ""C:\\Users\\Selene\\miniconda3\\lib\\site-packages\\IPython\\core\\interactiveshell.py"", line 3444, in run_code', '    exec(code_obj, self.user_global_ns, self.user_ns)', '  File ""C:\\Users\\Selene\\AppData\\Local\\Temp/ipykernel_48820/92798003.py"", line 5, in <module>', ""    get_ipython().run_line_magic('load_ext', 'wut')"", '  File ""C:\\Users\\Selene\\miniconda3\\lib\\site-packages\\IPython\\core\\interactiveshell.py"", line 2351, in run_line_magic', '    result = fn(*args, **kwargs)', '  File ""C:\\Users\\Selene\\miniconda3\\lib\\site-packages\\decorator.py"", line 232, in fun', '    return caller(func, *(extras + args), **kw)', '  File ""C:\\Users\\Selene\\miniconda3\\lib\\site-packages\\IPython\\core\\magic.py"", line 187, in <lambda>', '    call = lambda f, *a, **k: f(*a, **k)', '  File ""C:\\Users\\Selene\\miniconda3\\lib\\site-packages\\IPython\\core\\magics\\extension.py"", line 33, in load_ext', '    res = self.shell.extension_manager.load_extension(module_str)', '  File ""C:\\Users\\Selene\\miniconda3\\lib\\site-packages\\IPython\\core\\extensions.py"", line 80, in load_extension', '    mod = import_module(module_str)', '  File ""C:\\Users\\Selene\\miniconda3\\lib\\importlib\\__init__.py"", line 127, in import_module', '    return _bootstrap._gcd_import(name[level:], package, level)', '  File ""<frozen importlib._bootstrap>"", line 1030, in _gcd_import', '  File ""<frozen importlib._bootstrap>"", line 1007, in _find_and_load', '  File ""<frozen importlib._bootstrap>"", line 984, in _find_and_load_unlocked', ""ModuleNotFoundError: No module named 'wut'""]"
97,SyntaxError,"invalid syntax (Temp/ipykernel_48820/2051734545.py, line 5)",0,,2022-03-03 14:57:08.584680,"[('return compile(source, filename, symbol, self.flags | PyCF_ONLY_AST, 1)', 101)]","['Traceback (most recent call last):', '  File ""C:\\Users\\Selene\\miniconda3\\lib\\site-packages\\IPython\\core\\interactiveshell.py"", line 3143, in run_cell_async', '    code_ast = compiler.ast_parse(cell, filename=cell_name)', '  File ""C:\\Users\\Selene\\miniconda3\\lib\\site-packages\\IPython\\core\\compilerop.py"", line 101, in ast_parse', '    return compile(source, filename, symbol, self.flags | PyCF_ONLY_AST, 1)', '  File ""C:\\Users\\Selene\\AppData\\Local\\Temp/ipykernel_48820/2051734545.py"", line 5', '    load_ext wut', '             ^', 'SyntaxError: invalid syntax']"
98,ModuleNotFoundError,No module named 'wut',0,,2022-03-03 14:57:13.481428,"[(""get_ipython().run_line_magic('load_ext', 'wut')"", 5), ('result = fn(*args, **kwargs)', 2351)]","['Traceback (most recent call last):', '  File ""C:\\Users\\Selene\\miniconda3\\lib\\site-packages\\IPython\\core\\interactiveshell.py"", line 3444, in run_code', '    exec(code_obj, self.user_global_ns, self.user_ns)', '  File ""C:\\Users\\Selene\\AppData\\Local\\Temp/ipykernel_48820/92798003.py"", line 5, in <module>', ""    get_ipython().run_line_magic('load_ext', 'wut')"", '  File ""C:\\Users\\Selene\\miniconda3\\lib\\site-packages\\IPython\\core\\interactiveshell.py"", line 2351, in run_line_magic', '    result = fn(*args, **kwargs)', '  File ""C:\\Users\\Selene\\miniconda3\\lib\\site-packages\\decorator.py"", line 232, in fun', '    return caller(func, *(extras + args), **kw)', '  File ""C:\\Users\\Selene\\miniconda3\\lib\\site-packages\\IPython\\core\\magic.py"", line 187, in <lambda>', '    call = lambda f, *a, **k: f(*a, **k)', '  File ""C:\\Users\\Selene\\miniconda3\\lib\\site-packages\\IPython\\core\\magics\\extension.py"", line 33, in load_ext', '    res = self.shell.extension_manager.load_extension(module_str)', '  File ""C:\\Users\\Selene\\miniconda3\\lib\\site-packages\\IPython\\core\\extensions.py"", line 80, in load_extension', '    mod = import_module(module_str)', '  File ""C:\\Users\\Selene\\miniconda3\\lib\\importlib\\__init__.py"", line 127, in import_module', '    return _bootstrap._gcd_import(name[level:], package, level)', '  File ""<frozen importlib._bootstrap>"", line 1030, in _gcd_import', '  File ""<frozen importlib._bootstrap>"", line 1007, in _find_and_load', '  File ""<frozen importlib._bootstrap>"", line 984, in _find_and_load_unlocked', ""ModuleNotFoundError: No module named 'wut'""]"
99,UsageError,Line magic function `%iwut` not found.,0,,2022-03-03 14:57:22.185612,"[(""get_ipython().run_line_magic('iwut', 'on')"", 6), ('raise UsageError(etpl % (magic_name, extra))', 2331)]","['Traceback (most recent call last):', '  File ""C:\\Users\\Selene\\miniconda3\\lib\\site-packages\\IPython\\core\\interactiveshell.py"", line 3444, in run_code', '    exec(code_obj, self.user_global_ns, self.user_ns)', '  File ""C:\\Users\\Selene\\AppData\\Local\\Temp/ipykernel_48820/922990476.py"", line 6, in <module>', ""    get_ipython().run_line_magic('iwut', 'on')"", '  File ""C:\\Users\\Selene\\miniconda3\\lib\\site-packages\\IPython\\core\\interactiveshell.py"", line 2331, in run_line_magic', '    raise UsageError(etpl % (magic_name, extra))', 'IPython.core.error.UsageError: Line magic function `%iwut` not found.']"
100,AttributeError,'NoneType' object has no attribute 'hello',0,,2022-03-03 14:57:29.246180,"[('a.hello', 2)]","['Traceback (most recent call last):', '  File ""C:\\Users\\Selene\\miniconda3\\lib\\site-packages\\IPython\\core\\interactiveshell.py"", line 3444, in run_code', '    exec(code_obj, self.user_global_ns, self.user_ns)', '  File ""C:\\Users\\Selene\\AppData\\Local\\Temp/ipykernel_48820/2399003099.py"", line 2, in <module>', '    a.hello', ""AttributeError: 'NoneType' object has no attribute 'hello'""]"
101,UsageError,Line magic function `%iwut` not found.,0,,2022-03-03 14:57:39.964197,"[(""get_ipython().run_line_magic('iwut', 'on')"", 5), ('raise UsageError(etpl % (magic_name, extra))', 2331)]","['Traceback (most recent call last):', '  File ""C:\\Users\\Selene\\miniconda3\\lib\\site-packages\\IPython\\core\\interactiveshell.py"", line 3444, in run_code', '    exec(code_obj, self.user_global_ns, self.user_ns)', '  File ""C:\\Users\\Selene\\AppData\\Local\\Temp/ipykernel_48820/882961187.py"", line 5, in <module>', ""    get_ipython().run_line_magic('iwut', 'on')"", '  File ""C:\\Users\\Selene\\miniconda3\\lib\\site-packages\\IPython\\core\\interactiveshell.py"", line 2331, in run_line_magic', '    raise UsageError(etpl % (magic_name, extra))', 'IPython.core.error.UsageError: Line magic function `%iwut` not found.']"
102,UsageError,Line magic function `%wut` not found.,0,,2022-03-07 17:44:38.308614,"[(""get_ipython().run_line_magic('wut', 'on')"", 5), ('raise UsageError(etpl % (magic_name, extra))', 2331)]","['Traceback (most recent call last):', '  File ""C:\\Users\\Selene\\miniconda3\\lib\\site-packages\\IPython\\core\\interactiveshell.py"", line 3444, in run_code', '    exec(code_obj, self.user_global_ns, self.user_ns)', '  File ""C:\\Users\\Selene\\AppData\\Local\\Temp/ipykernel_37524/755400964.py"", line 5, in <module>', ""    get_ipython().run_line_magic('wut', 'on')"", '  File ""C:\\Users\\Selene\\miniconda3\\lib\\site-packages\\IPython\\core\\interactiveshell.py"", line 2331, in run_line_magic', '    raise UsageError(etpl % (magic_name, extra))', 'IPython.core.error.UsageError: Line magic function `%wut` not found.']"
103,AttributeError,'NoneType' object has no attribute 'hello',0,,2022-03-07 17:44:41.796286,"[('a.hello', 2)]","['Traceback (most recent call last):', '  File ""C:\\Users\\Selene\\miniconda3\\lib\\site-packages\\IPython\\core\\interactiveshell.py"", line 3444, in run_code', '    exec(code_obj, self.user_global_ns, self.user_ns)', '  File ""C:\\Users\\Selene\\AppData\\Local\\Temp/ipykernel_37524/2399003099.py"", line 2, in <module>', '    a.hello', ""AttributeError: 'NoneType' object has no attribute 'hello'""]"
104,AttributeError,'NoneType' object has no attribute 'hello',0,,2022-03-07 17:47:41.074624,"[('a.hello', 2)]","['Traceback (most recent call last):', '  File ""C:\\Users\\Selene\\miniconda3\\lib\\site-packages\\IPython\\core\\interactiveshell.py"", line 3444, in run_code', '    exec(code_obj, self.user_global_ns, self.user_ns)', '  File ""C:\\Users\\Selene\\AppData\\Local\\Temp/ipykernel_51624/2399003099.py"", line 2, in <module>', '    a.hello', ""AttributeError: 'NoneType' object has no attribute 'hello'""]"
105,SyntaxError,"invalid syntax (Temp/ipykernel_51624/1035764680.py, line 3)",0,,2022-03-07 17:48:04.581099,"[('return compile(source, filename, symbol, self.flags | PyCF_ONLY_AST, 1)', 101)]","['Traceback (most recent call last):', '  File ""C:\\Users\\Selene\\miniconda3\\lib\\site-packages\\IPython\\core\\interactiveshell.py"", line 3143, in run_cell_async', '    code_ast = compiler.ast_parse(cell, filename=cell_name)', '  File ""C:\\Users\\Selene\\miniconda3\\lib\\site-packages\\IPython\\core\\compilerop.py"", line 101, in ast_parse', '    return compile(source, filename, symbol, self.flags | PyCF_ONLY_AST, 1)', '  File ""C:\\Users\\Selene\\AppData\\Local\\Temp/ipykernel_51624/1035764680.py"", line 3', '    2a', '     ^', 'SyntaxError: invalid syntax']"
106,SyntaxError,"invalid syntax (Temp/ipykernel_51624/735764527.py, line 3)",0,,2022-03-07 17:48:27.182836,"[('return compile(source, filename, symbol, self.flags | PyCF_ONLY_AST, 1)', 101)]","['Traceback (most recent call last):', '  File ""C:\\Users\\Selene\\miniconda3\\lib\\site-packages\\IPython\\core\\interactiveshell.py"", line 3143, in run_cell_async', '    code_ast = compiler.ast_parse(cell, filename=cell_name)', '  File ""C:\\Users\\Selene\\miniconda3\\lib\\site-packages\\IPython\\core\\compilerop.py"", line 101, in ast_parse', '    return compile(source, filename, symbol, self.flags | PyCF_ONLY_AST, 1)', '  File ""C:\\Users\\Selene\\AppData\\Local\\Temp/ipykernel_51624/735764527.py"", line 3', '    2a', '     ^', 'SyntaxError: invalid syntax']"
107,SyntaxError,"invalid syntax (Temp/ipykernel_51624/735764527.py, line 3)",0,,2022-03-07 17:48:34.980852,"[('return compile(source, filename, symbol, self.flags | PyCF_ONLY_AST, 1)', 101)]","['Traceback (most recent call last):', '  File ""C:\\Users\\Selene\\miniconda3\\lib\\site-packages\\IPython\\core\\interactiveshell.py"", line 3143, in run_cell_async', '    code_ast = compiler.ast_parse(cell, filename=cell_name)', '  File ""C:\\Users\\Selene\\miniconda3\\lib\\site-packages\\IPython\\core\\compilerop.py"", line 101, in ast_parse', '    return compile(source, filename, symbol, self.flags | PyCF_ONLY_AST, 1)', '  File ""C:\\Users\\Selene\\AppData\\Local\\Temp/ipykernel_51624/735764527.py"", line 3', '    2a', '     ^', 'SyntaxError: invalid syntax']"
108,SyntaxError,"invalid syntax (Temp/ipykernel_51624/3139040304.py, line 2)",0,,2022-03-07 17:48:57.751641,"[('return compile(source, filename, symbol, self.flags | PyCF_ONLY_AST, 1)', 101)]","['Traceback (most recent call last):', '  File ""C:\\Users\\Selene\\miniconda3\\lib\\site-packages\\IPython\\core\\interactiveshell.py"", line 3143, in run_cell_async', '    code_ast = compiler.ast_parse(cell, filename=cell_name)', '  File ""C:\\Users\\Selene\\miniconda3\\lib\\site-packages\\IPython\\core\\compilerop.py"", line 101, in ast_parse', '    return compile(source, filename, symbol, self.flags | PyCF_ONLY_AST, 1)', '  File ""C:\\Users\\Selene\\AppData\\Local\\Temp/ipykernel_51624/3139040304.py"", line 2', '    2a', '     ^', 'SyntaxError: invalid syntax']"
109,AttributeError,module 'numpy' has no attribute 'aragne',0,,2022-03-07 17:49:01.217572,"[(""np.aragne('HI')"", 1), ('raise AttributeError(""module {!r} has no attribute ""', 313)]","['Traceback (most recent call last):', '  File ""C:\\Users\\Selene\\miniconda3\\lib\\site-packages\\IPython\\core\\interactiveshell.py"", line 3444, in run_code', '    exec(code_obj, self.user_global_ns, self.user_ns)', '  File ""C:\\Users\\Selene\\AppData\\Local\\Temp/ipykernel_51624/1147446779.py"", line 1, in <module>', ""    np.aragne('HI')"", '  File ""C:\\Users\\Selene\\miniconda3\\lib\\site-packages\\numpy\\__init__.py"", line 313, in __getattr__', '    raise AttributeError(""module {!r} has no attribute ""', ""AttributeError: module 'numpy' has no attribute 'aragne'""]"
110,SyntaxError,"invalid syntax (Temp/ipykernel_51624/4137880794.py, line 1)",0,,2022-03-07 17:55:09.038602,"[('return compile(source, filename, symbol, self.flags | PyCF_ONLY_AST, 1)', 101)]","['Traceback (most recent call last):', '  File ""C:\\Users\\Selene\\miniconda3\\lib\\site-packages\\IPython\\core\\interactiveshell.py"", line 3143, in run_cell_async', '    code_ast = compiler.ast_parse(cell, filename=cell_name)', '  File ""C:\\Users\\Selene\\miniconda3\\lib\\site-packages\\IPython\\core\\compilerop.py"", line 101, in ast_parse', '    return compile(source, filename, symbol, self.flags | PyCF_ONLY_AST, 1)', '  File ""C:\\Users\\Selene\\AppData\\Local\\Temp/ipykernel_51624/4137880794.py"", line 1', '    2a', '     ^', 'SyntaxError: invalid syntax']"
111,TypeError,'int' object is not callable,0,,2022-03-10 03:08:06.680890,"[('3(2)', 1)]","['Traceback (most recent call last):', '  File ""C:\\Users\\Selene\\miniconda3\\lib\\site-packages\\IPython\\core\\interactiveshell.py"", line 3444, in run_code', '    exec(code_obj, self.user_global_ns, self.user_ns)', '  File ""C:\\Users\\Selene\\AppData\\Local\\Temp/ipykernel_31328/305253956.py"", line 1, in <module>', '    3(2)', ""TypeError: 'int' object is not callable""]"
112,AttributeError,'NoneType' object has no attribute 'hello',0,,2022-03-10 03:10:10.558582,"[('a.hello', 2)]","['Traceback (most recent call last):', '  File ""C:\\Users\\Selene\\miniconda3\\lib\\site-packages\\IPython\\core\\interactiveshell.py"", line 3444, in run_code', '    exec(code_obj, self.user_global_ns, self.user_ns)', '  File ""C:\\Users\\Selene\\AppData\\Local\\Temp/ipykernel_11256/2399003099.py"", line 2, in <module>', '    a.hello', ""AttributeError: 'NoneType' object has no attribute 'hello'""]"
113,TypeError,'int' object is not callable,0,,2022-03-10 03:12:29.258846,"[('3(2)', 1)]","['Traceback (most recent call last):', '  File ""C:\\Users\\Selene\\miniconda3\\lib\\site-packages\\IPython\\core\\interactiveshell.py"", line 3444, in run_code', '    exec(code_obj, self.user_global_ns, self.user_ns)', '  File ""C:\\Users\\Selene\\AppData\\Local\\Temp/ipykernel_17208/305253956.py"", line 1, in <module>', '    3(2)', ""TypeError: 'int' object is not callable""]"
114,AttributeError,'NoneType' object has no attribute 'hello',0,,2022-03-10 03:12:29.480850,"[('a.hello', 2)]","['Traceback (most recent call last):', '  File ""C:\\Users\\Selene\\miniconda3\\lib\\site-packages\\IPython\\core\\interactiveshell.py"", line 3444, in run_code', '    exec(code_obj, self.user_global_ns, self.user_ns)', '  File ""C:\\Users\\Selene\\AppData\\Local\\Temp/ipykernel_17208/2399003099.py"", line 2, in <module>', '    a.hello', ""AttributeError: 'NoneType' object has no attribute 'hello'""]"
115,NameError,name 'data8' is not defined,0,,2022-03-10 03:12:29.636665,"[('data8', 15)]","['Traceback (most recent call last):', '  File ""C:\\Users\\Selene\\miniconda3\\lib\\site-packages\\IPython\\core\\interactiveshell.py"", line 3444, in run_code', '    exec(code_obj, self.user_global_ns, self.user_ns)', '  File ""C:\\Users\\Selene\\AppData\\Local\\Temp/ipykernel_17208/4159590661.py"", line 15, in <module>', '    data8', ""NameError: name 'data8' is not defined""]"
116,UsageError,Cell magic `%%wut` not found.,0,,2022-03-10 03:12:29.808029,"[(""get_ipython().run_cell_magic('wut', '', '2a\\n')"", 1), ('raise UsageError(etpl.format(magic_name, extra))', 2384)]","['Traceback (most recent call last):', '  File ""C:\\Users\\Selene\\miniconda3\\lib\\site-packages\\IPython\\core\\interactiveshell.py"", line 3444, in run_code', '    exec(code_obj, self.user_global_ns, self.user_ns)', '  File ""C:\\Users\\Selene\\AppData\\Local\\Temp/ipykernel_17208/2809236449.py"", line 1, in <module>', ""    get_ipython().run_cell_magic('wut', '', '2a\\n')"", '  File ""C:\\Users\\Selene\\miniconda3\\lib\\site-packages\\IPython\\core\\interactiveshell.py"", line 2384, in run_cell_magic', '    raise UsageError(etpl.format(magic_name, extra))', 'IPython.core.error.UsageError: Cell magic `%%wut` not found.']"
117,AttributeError,module 'numpy' has no attribute 'aragne',0,,2022-03-10 03:12:29.975109,"[(""np.aragne('HI')"", 1), ('raise AttributeError(""module {!r} has no attribute ""', 313)]","['Traceback (most recent call last):', '  File ""C:\\Users\\Selene\\miniconda3\\lib\\site-packages\\IPython\\core\\interactiveshell.py"", line 3444, in run_code', '    exec(code_obj, self.user_global_ns, self.user_ns)', '  File ""C:\\Users\\Selene\\AppData\\Local\\Temp/ipykernel_17208/1147446779.py"", line 1, in <module>', ""    np.aragne('HI')"", '  File ""C:\\Users\\Selene\\miniconda3\\lib\\site-packages\\numpy\\__init__.py"", line 313, in __getattr__', '    raise AttributeError(""module {!r} has no attribute ""', ""AttributeError: module 'numpy' has no attribute 'aragne'""]"
118,IndexError,list index out of range,0,,2022-03-10 03:12:30.140671,"[('[2][1]', 1)]","['Traceback (most recent call last):', '  File ""C:\\Users\\Selene\\miniconda3\\lib\\site-packages\\IPython\\core\\interactiveshell.py"", line 3444, in run_code', '    exec(code_obj, self.user_global_ns, self.user_ns)', '  File ""C:\\Users\\Selene\\AppData\\Local\\Temp/ipykernel_17208/1686336973.py"", line 1, in <module>', '    [2][1]', 'IndexError: list index out of range']"
119,AttributeError,module 'numpy' has no attribute 'hi',0,,2022-03-10 03:12:30.384187,"[('np.hi', 1), ('raise AttributeError(""module {!r} has no attribute ""', 313)]","['Traceback (most recent call last):', '  File ""C:\\Users\\Selene\\miniconda3\\lib\\site-packages\\IPython\\core\\interactiveshell.py"", line 3444, in run_code', '    exec(code_obj, self.user_global_ns, self.user_ns)', '  File ""C:\\Users\\Selene\\AppData\\Local\\Temp/ipykernel_17208/1570163000.py"", line 1, in <module>', '    np.hi', '  File ""C:\\Users\\Selene\\miniconda3\\lib\\site-packages\\numpy\\__init__.py"", line 313, in __getattr__', '    raise AttributeError(""module {!r} has no attribute ""', ""AttributeError: module 'numpy' has no attribute 'hi'""]"
120,NameError,name 'Table' is not defined,0,,2022-03-10 03:12:30.544816,"[('Table()', 1)]","['Traceback (most recent call last):', '  File ""C:\\Users\\Selene\\miniconda3\\lib\\site-packages\\IPython\\core\\interactiveshell.py"", line 3444, in run_code', '    exec(code_obj, self.user_global_ns, self.user_ns)', '  File ""C:\\Users\\Selene\\AppData\\Local\\Temp/ipykernel_17208/4234517321.py"", line 1, in <module>', '    Table()', ""NameError: name 'Table' is not defined""]"
121,ValueError,invalid literal for int() with base 10: 'HI',0,,2022-03-10 03:12:30.779170,"[('int(""HI"")', 1)]","['Traceback (most recent call last):', '  File ""C:\\Users\\Selene\\miniconda3\\lib\\site-packages\\IPython\\core\\interactiveshell.py"", line 3444, in run_code', '    exec(code_obj, self.user_global_ns, self.user_ns)', '  File ""C:\\Users\\Selene\\AppData\\Local\\Temp/ipykernel_17208/532684827.py"", line 1, in <module>', '    int(""HI"")', ""ValueError: invalid literal for int() with base 10: 'HI'""]"
122,ZeroDivisionError,division by zero,0,,2022-03-10 03:12:30.988360,"[('f()', 4), ('3 / 0', 2)]","['Traceback (most recent call last):', '  File ""C:\\Users\\Selene\\miniconda3\\lib\\site-packages\\IPython\\core\\interactiveshell.py"", line 3444, in run_code', '    exec(code_obj, self.user_global_ns, self.user_ns)', '  File ""C:\\Users\\Selene\\AppData\\Local\\Temp/ipykernel_17208/2851013969.py"", line 4, in <module>', '    f()', '  File ""C:\\Users\\Selene\\AppData\\Local\\Temp/ipykernel_17208/2851013969.py"", line 2, in f', '    3 / 0', 'ZeroDivisionError: division by zero']"
123,ZeroDivisionError,division by zero,0,,2022-03-10 03:12:31.141057,"[('f()', 1), ('3 / 0', 2)]","['Traceback (most recent call last):', '  File ""C:\\Users\\Selene\\miniconda3\\lib\\site-packages\\IPython\\core\\interactiveshell.py"", line 3444, in run_code', '    exec(code_obj, self.user_global_ns, self.user_ns)', '  File ""C:\\Users\\Selene\\AppData\\Local\\Temp/ipykernel_17208/3782956317.py"", line 1, in <module>', '    f()', '  File ""C:\\Users\\Selene\\AppData\\Local\\Temp/ipykernel_17208/2851013969.py"", line 2, in f', '    3 / 0', 'ZeroDivisionError: division by zero']"
124,AttributeError,'NoneType' object has no attribute 'hello',0,,2022-03-10 03:12:40.283021,"[('a.hello', 2)]","['Traceback (most recent call last):', '  File ""C:\\Users\\Selene\\miniconda3\\lib\\site-packages\\IPython\\core\\interactiveshell.py"", line 3444, in run_code', '    exec(code_obj, self.user_global_ns, self.user_ns)', '  File ""C:\\Users\\Selene\\AppData\\Local\\Temp/ipykernel_17208/2399003099.py"", line 2, in <module>', '    a.hello', ""AttributeError: 'NoneType' object has no attribute 'hello'""]"
